<?xml version="1.0" ?>
<!-- =================================================================================== -->
<!-- |    This document was autogenerated by xacro from /home/nikita/moveit_ws/src/ETU_RoboHub/solutions/my_first_manipulator/urdf/lrmate200id7h.xacro | -->
<!-- |    EDITING THIS FILE BY HAND IS NOT RECOMMENDED                                 | -->
<!-- =================================================================================== -->
<robot name="fanuc_lrmate200id7h">
    <material name="blue">
        <color rgba="0 0 0.8 1" />
    </material>
    <material name="white">
        <color rgba="1 1 1 1" />
    </material>
    <link name="base">
        <visual>
            <origin rpy="0 0 0" xyz="0 0 0.025" />
            <geometry>
                <cylinder length="0.05" radius="0.2" />
            </geometry>
            <material name="blue" />
        </visual>
        <collision>
            <origin rpy="0 0 0" xyz="0 0 0.025" />
            <geometry>
                <cylinder length="0.05" radius="0.2" />
            </geometry>
        </collision>
        <inertial>
            <mass value="0.1" />
            <origin xyz="0 0 0" rpy="0 0 0" />
            <inertia ixx="0.03" iyy="0.03" izz="0.03" ixy="0.0" ixz="0.0" iyz="0.0" />
        </inertial>
    </link>
    <joint name="base_2_link_0" type="fixed">
        <origin rpy="0 0 0" xyz="0 0 0.05" />
        <parent link="base" />
        <child link="link_0" />
    </joint>
    <link name="link_0">
        <visual>
            <origin rpy="0 0 0" xyz="0 0 0.075" />
            <geometry>
                <cylinder length="0.15" radius="0.07" />
            </geometry>
            <material name="white" />
        </visual>
        <collision>
            <origin rpy="0 0 0" xyz="0 0 0.075" />
            <geometry>
                <cylinder length="0.15" radius="0.07" />
            </geometry>
        </collision>
        <inertial>
            <mass value="0.1" />
            <origin xyz="0 0 0" rpy="0 0 0" />
            <inertia ixx="0.03" iyy="0.03" izz="0.03" ixy="0.0" ixz="0.0" iyz="0.0" />
        </inertial>
    </link>
    <joint name="joint_1" type="revolute">
        <origin rpy="0 0 0" xyz="0 0 0.150" />
        <parent link="link_0" />
        <child link="link_1" />
        <axis xyz="0 0 1" />
        <limit effort="0" lower="-2.9670597283903604" upper="2.9670597283903604" velocity="6.457718232379019" />
    </joint>
    <link name="link_1">
        <visual>
            <origin rpy="0 0 0" xyz="0 0 0.075" />
            <geometry>
                <cylinder length="0.15" radius="0.07" />
            </geometry>
            <material name="blue" />
        </visual>
        <collision>
            <origin rpy="0 0 0" xyz="0 0 0.075" />
            <geometry>
                <cylinder length="0.15" radius="0.07" />
            </geometry>
        </collision>
        <inertial>
            <mass value="0.1" />
            <origin xyz="0 0 0" rpy="0 0 0" />
            <inertia ixx="0.03" iyy="0.03" izz="0.03" ixy="0.0" ixz="0.0" iyz="0.0" />
        </inertial>
    </link>
    <joint name="joint_2" type="revolute">
        <origin rpy="0 0 0" xyz="0 0 0.150" />
        <parent link="link_1" />
        <child link="link_2" />
        <axis xyz="-1 0 0" />
        <limit effort="0" lower="-0.8726646259971648" upper="1.7453292519943295" velocity="5.410520681182422" />
    </joint>
    <link name="link_2">
        <visual>
            <origin rpy="0 0 0" xyz="0 0 0.150" />
            <geometry>
                <box size="0.12 0.12 0.3" />
            </geometry>
            <material name="white" />
        </visual>
        <collision>
            <origin rpy="0 0 0" xyz="0 0 0.150" />
            <geometry>
                <box size="0.12 0.12 0.3" />
            </geometry>
        </collision>
        <inertial>
            <mass value="0.1" />
            <origin xyz="0 0 0" rpy="0 0 0" />
            <inertia ixx="0.03" iyy="0.03" izz="0.03" ixy="0.0" ixz="0.0" iyz="0.0" />
        </inertial>
    </link>
    <joint name="joint_3" type="revolute">
        <origin rpy="0 0 0" xyz="0 0 0.3" />
        <parent link="link_2" />
        <child link="link_3" />
        <axis xyz="-1 0 0" />
        <limit effort="0" lower="-1.2217304763960306" upper="1.7453292519943295" velocity="7.155849933176751" />
    </joint>
    <link name="link_3">
        <visual>
            <origin rpy="0 0 0" xyz="0 0 0.05" />
            <geometry>
                <cylinder length="0.1" radius="0.05" />
            </geometry>
            <material name="blue" />
        </visual>
        <collision>
            <origin rpy="0 0 0" xyz="0 0 0.05" />
            <geometry>
                <cylinder length="0.1" radius="0.05" />
            </geometry>
        </collision>
        <inertial>
            <mass value="0.1" />
            <origin xyz="0 0 0" rpy="0 0 0" />
            <inertia ixx="0.03" iyy="0.03" izz="0.03" ixy="0.0" ixz="0.0" iyz="0.0" />
        </inertial>
    </link>
    <joint name="joint_4" type="revolute">
        <origin rpy="0 0 0" xyz="0 0 0.1" />
        <parent link="link_3" />
        <child link="link_4" />
        <axis xyz="0 0 1" />
        <limit effort="0" lower="-3.3161255787892263" upper="3.3161255787892263" velocity="9.599310885968812" />
    </joint>
    <link name="link_4">
        <visual>
            <origin rpy="0 0 0" xyz="0 0 0.05" />
            <geometry>
                <cylinder length="0.1" radius="0.05" />
            </geometry>
            <material name="white" />
        </visual>
        <collision>
            <origin rpy="0 0 0" xyz="0 0 0.05" />
            <geometry>
                <cylinder length="0.1" radius="0.05" />
            </geometry>
        </collision>
        <inertial>
            <mass value="0.1" />
            <origin xyz="0 0 0" rpy="0 0 0" />
            <inertia ixx="0.03" iyy="0.03" izz="0.03" ixy="0.0" ixz="0.0" iyz="0.0" />
        </inertial>
    </link>
    <joint name="joint_5" type="revolute">
        <origin rpy="0 0 0" xyz="0 0 0.1" />
        <parent link="link_4" />
        <child link="link_5" />
        <axis xyz="-1 0 0" />
        <limit effort="0" lower="-2.181661564992912" upper="2.181661564992912" velocity="9.512044423369096" />
    </joint>
    <link name="link_5">
        <visual>
            <origin rpy="0 0 0" xyz="0 0 0.040" />
            <geometry>
                <box size="0.08 0.08 0.08" />
            </geometry>
            <material name="blue" />
        </visual>
        <collision>
            <origin rpy="0 0 0" xyz="0 0 0.040" />
            <geometry>
                <box size="0.08 0.08 0.08" />
            </geometry>
        </collision>
        <inertial>
            <mass value="0.1" />
            <origin xyz="0 0 0" rpy="0 0 0" />
            <inertia ixx="0.03" iyy="0.03" izz="0.03" ixy="0.0" ixz="0.0" iyz="0.0" />
        </inertial>
    </link>
    <joint name="joint_6" type="revolute">
        <origin rpy="0 -1.5707963267948966 0" xyz="0.0 0 0.080" />
        <parent link="link_5" />
        <child link="flange" />
        <axis xyz="-1 0 0" />
        <limit effort="0" lower="-6.283185307179586" upper="6.283185307179586" velocity="17.453292519943297" />
    </joint>
    <link name="flange" />
    <joint name="flange_2_tool" type="fixed">
        <origin rpy="0 0 0" xyz="0 0 0" />
        <parent link="flange" />
        <child link="toolb" />
    </joint>
    <link name="toolb">
        <visual>
            <origin rpy="0 -1.5707963267948966 0" xyz="0.035 0 0" />
            <geometry>
                <cylinder length="0.07" radius="0.04" />
            </geometry>
            <material name="t">
                <color rgba="0.1 0.6 0.81 1" />
            </material>
        </visual>
        <collision>
            <origin rpy="0 -1.5707963267948966 0" xyz="0.035 0 0" />
            <geometry>
                <cylinder length="0.07" radius="0.02" />
            </geometry>
        </collision>
        <inertial>
            <mass value="1" />
            <inertia ixx="1" ixy="1" ixz="1" iyy="1" iyz="1" izz="1" />
            <origin xyz="0 0 0" rpy="0 0 0" />
        </inertial>
    </link>
    <joint name="toolb_2_tool_0" type="fixed">
        <origin rpy="0 0 0" xyz="0.07 0 0" />
        <parent link="toolb" />
        <child link="tool_0" />
    </joint>
    <link name="tool_0">
        <visual>
            <origin rpy="0 -1.5707963267948966 0" xyz="0.02 0 0" />
            <geometry>
                <box size="0.04 0.04 0.04" />
            </geometry>
            <material name="t_0">
                <color rgba="0.1 0.8 0.81 1" />
            </material>
        </visual>
        <collision>
            <origin rpy="0 -1.5707963267948966 0" xyz="0.02 0 0" />
            <geometry>
                <box size="0.04 0.04 0.04" />
            </geometry>
        </collision>
        <inertial>
            <mass value="0.1" />
            <origin xyz="0 0 0" rpy="0 0 0" />
            <inertia ixx="0.03" iyy="0.03" izz="0.03" ixy="0.0" ixz="0.0" iyz="0.0" />
        </inertial>
    </link>
    <joint name="linear_L" type="prismatic">
        <origin rpy="0 0 0" xyz="0.04 -0.035 0" />
        <parent link="tool_0" />
        <child link="leftfinger" />
        <axis xyz="0 1 0" />
        <limit effort="100" lower="0" upper="0.01" velocity="0.2" />
    </joint>
    <link name="leftfinger">
        <visual>
            <origin rpy="0 0 0" xyz="0.025 0.0025 0" />
            <geometry>
                <box size="0.05 0.005 0.05" />
            </geometry>
        </visual>
        <collision>
            <origin rpy="0 0 0" xyz="0.025 0.0025 0" />
            <geometry>
                <box size="0.05 0.005 0.05" />
            </geometry>
        </collision>
        <inertial>
            <mass value="0.1" />
            <origin xyz="0 0 0" rpy="0 0 0" />
            <inertia ixx="0.03" iyy="0.03" izz="0.03" ixy="0.0" ixz="0.0" iyz="0.0" />
        </inertial>
    </link>
    <joint name="linear_R" type="prismatic">
        <origin rpy="0 0 0" xyz="0.04 0.035 0" />
        <parent link="tool_0" />
        <child link="rightfinger" />
        <axis xyz="0 -1 0" />
        <limit effort="100" lower="0" upper="0.01" velocity="0.2" />
    </joint>
    <link name="rightfinger">
        <visual>
            <origin rpy="0 0 0" xyz="0.025 -0.0025 0" />
            <geometry>
                <box size="0.05 0.005 0.05" />
            </geometry>
        </visual>
        <collision>
            <origin rpy="0 0 0" xyz="0.025 -0.0025 0" />
            <geometry>
                <box size="0.05 0.005 0.05" />
            </geometry>
        </collision>
        <inertial>
            <mass value="0.1" />
            <origin xyz="0 0 0" rpy="0 0 0" />
            <inertia ixx="0.03" iyy="0.03" izz="0.03" ixy="0.0" ixz="0.0" iyz="0.0" />
        </inertial>
    </link>
    <joint name="toolb_2_TCP" type="fixed">
        <origin rpy="0 0 0" xyz="0.16 0 0" />
        <parent link="toolb" />
        <child link="TCP" />
    </joint>
    <link name="TCP" />
    <transmission name="trans_joint_1">
        <type>transmission_interface/SimpleTransmission</type>
        <joint name="joint_1">
            <hardwareInterface>hardware_interface/PositionJointInterface</hardwareInterface>
        </joint>
        <actuator name="joint_1_motor">
            <hardwareInterface>hardware_interface/PositionJointInterface</hardwareInterface>
            <mechanicalReduction>1</mechanicalReduction>
        </actuator>
    </transmission>
    <transmission name="trans_joint_2">
        <type>transmission_interface/SimpleTransmission</type>
        <joint name="joint_2">
            <hardwareInterface>hardware_interface/PositionJointInterface</hardwareInterface>
        </joint>
        <actuator name="joint_2_motor">
            <hardwareInterface>hardware_interface/PositionJointInterface</hardwareInterface>
            <mechanicalReduction>1</mechanicalReduction>
        </actuator>
    </transmission>
    <transmission name="trans_joint_3">
        <type>transmission_interface/SimpleTransmission</type>
        <joint name="joint_3">
            <hardwareInterface>hardware_interface/PositionJointInterface</hardwareInterface>
        </joint>
        <actuator name="joint_3_motor">
            <hardwareInterface>hardware_interface/PositionJointInterface</hardwareInterface>
            <mechanicalReduction>1</mechanicalReduction>
        </actuator>
    </transmission>
    <transmission name="trans_joint_4">
        <type>transmission_interface/SimpleTransmission</type>
        <joint name="joint_4">
            <hardwareInterface>hardware_interface/PositionJointInterface</hardwareInterface>
        </joint>
        <actuator name="joint_4_motor">
            <hardwareInterface>hardware_interface/PositionJointInterface</hardwareInterface>
            <mechanicalReduction>1</mechanicalReduction>
        </actuator>
    </transmission>
    <transmission name="trans_joint_5">
        <type>transmission_interface/SimpleTransmission</type>
        <joint name="joint_5">
            <hardwareInterface>hardware_interface/PositionJointInterface</hardwareInterface>
        </joint>
        <actuator name="joint_5_motor">
            <hardwareInterface>hardware_interface/PositionJointInterface</hardwareInterface>
            <mechanicalReduction>1</mechanicalReduction>
        </actuator>
    </transmission>
    <transmission name="trans_joint_6">
        <type>transmission_interface/SimpleTransmission</type>
        <joint name="joint_6">
            <hardwareInterface>hardware_interface/PositionJointInterface</hardwareInterface>
        </joint>
        <actuator name="joint_6_motor">
            <hardwareInterface>hardware_interface/PositionJointInterface</hardwareInterface>
            <mechanicalReduction>1</mechanicalReduction>
        </actuator>
    </transmission>
    <transmission name="trans_linear_L">
        <type>transmission_interface/SimpleTransmission</type>
        <joint name="linear_L">
            <hardwareInterface>hardware_interface/EffortJointInterface</hardwareInterface>
        </joint>
        <actuator name="linear_L_motor">
            <hardwareInterface>hardware_interface/EffortJointInterface</hardwareInterface>
            <mechanicalReduction>1</mechanicalReduction>
        </actuator>
    </transmission>
    <transmission name="trans_linear_R">
        <type>transmission_interface/SimpleTransmission</type>
        <joint name="linear_R">
            <hardwareInterface>hardware_interface/EffortJointInterface</hardwareInterface>
        </joint>
        <actuator name="linear_R_motor">
            <hardwareInterface>hardware_interface/EffortJointInterface</hardwareInterface>
            <mechanicalReduction>1</mechanicalReduction>
        </actuator>
    </transmission>
    <gazebo>
        <plugin name="gazebo_ros_control" filename="libgazebo_ros_control.so">
            <robotNamespace>/</robotNamespace>
        </plugin>
    </gazebo>
</robot>

